Workbook

Sheet Instruções
A1: N2 — planejamento do backlog
A3: Campo | B3: Conteúdo | C3: Observação
A4: Objetivo | B4: Planejar tarefas específicas da N2 e entregar quatro diagramas UML com criação passo a passo.
A5: Situação | B5: Rascunho de planejamento. Datas e esforços devem ser aprovados pelo grupo; nenhuma tarefa está declarada concluída.
A6: Data-base | B6: 46300
A7: Prazo provisório | B7: 46339
A8: Premissa de prazo | B8: Sem data acadêmica informada. Seis semanas, de 05/10/2026 a 13/11/2026; ajustar ao calendário da disciplina.
A9: Calendário | B9: Segunda a sexta; 12/10 e 02/11 fora do cronograma. Feriados locais e calendário acadêmico a confirmar.
A10: Disponibilidade | B10: Limite provisório de 4 horas em um dia alocado por integrante. Esforço total: 184 h; 36–38 h por pessoa nas seis semanas.
A11: Estimativa | B11: Horas para revisar/integrar entregas e PRs existentes, corrigir lacunas e validar. Se for necessário reescrever, reestimar.
A12: Fontes | B12: README.md, PROJECT_BACKLOG.md, fluxos-de-usuario.md, schema/DER/UML locais, VALIDACAO_LOCAL.md e auditoria GitHub local de 05/10/2026.
A13: Material da aula | B13: Exemplo N2 Parte 1 / Exemplo Atividade.md não estava disponível. Conferência com esse modelo permanece pendente.
A14: Estado de PRs | B14: Referências dos PRs vêm da auditoria local; confirmar estado real no GitHub antes de integrar ou marcar concluído.
A15: Escopo local | B15: Nenhum push, PR, merge, publicação, provisionamento ou entrega acadêmica feito pela geração desta planilha.
A16: Como editar | B16: Filtre por responsável e ajuste esforço/datas/status. Resumo e validação de dependências recalculam em Excel; o cronograma de horas é a fotografia da alocação original e deve ser revisto após alterar tarefas.
A17: Dependências | B17: Uma tarefa só começa após o prazo das predecessoras. Coluna O confere IDs e datas. Datas de início/prazo são valores de data Excel.
A18: Critério de conclusão | B18: Status Concluída com evidência exige artefato, teste/revisão e aceite; configuração de variável ou PR aberto não comprova persistência real.
A19: Diagramas | B19: Abrir ../README.md para passo a passo e SVGs. Fontes PlantUML e desenhos SVG são fornecidos; a composição SVG é local, sem renderização remota.
A20: Margem final | B20: D09 reservado para 13/11/2026; intervalos livres antes dele são margem para correções e revisão, não tarefas omitidas.

Sheet Backlog N2
A1: Backlog N2 — tarefas, responsáveis e prazos
A2: 45 tarefas • 5 integrantes • prazo provisório 13/11/2026 • todos os status aguardam validação do grupo
A4: ID | B4: Card de referência | C4: Tarefa | D4: Responsável | E4: Esforço (h) | F4: Início | G4: Prazo | H4: Predecessoras | I4: Prioridade | J4: Status | K4: Entregável / critério de aceite | L4: Requisitos | M4: Fase | N4: Evidência / pendência | O4: Dependências
A5: A01 | B5: N2-PLAN / ajustes N1 | C5: Fechar escopo e conferir material da atividade | D5: Alyson de Lima de Oliveira | E5: 2 | F5: 46300 | G5: 46300 | I5: P0 | J5: Planejada — validar com o grupo | K5: Lista de pendências do README conciliada; modelo da aula e prazo confirmados com equipe | L5: RF01–RF48 | M5: Planejamento | N5: Material de aula e prazo ainda não fornecidos | O5: =IF(F5<=G5,"OK","Rever datas") -> OK
A6: A02 | B6: N2-P1-CU | C6: Revisar caso de uso e seu passo a passo | D6: Alyson de Lima de Oliveira | E6: 4 | F6: 46301 | G6: 46301 | H6: A01 | I6: P0 | J6: Planejada — validar com o grupo | K6: Atores, fronteira, associações e include/extend conferidos; aluno só acessa gabarito liberado | L6: RF01–RF48 | M6: Modelagem | N6: Rascunho entregue nesta atividade; validação do grupo pendente | O6: =IF(AND(COUNTIF($A$5:$A$49,"A01")=1,F6>MAX(SUMIF($A$5:$A$49,"A01",$G$5:$G$49))),"OK","Rever IDs/datas") -> OK
A7: D01 | B7: N1-INF-01 / ambiente N2 | C7: Reproduzir ambiente e definir versão Python/Node | D7: Diego Rafael da Silva Dornelles | E7: 4 | F7: 46301 | G7: 46301 | H7: A01 | I7: P0 | J7: Planejada — validar com o grupo | K7: Instalação limpa, API e frontend iniciam; versão validada registrada; dependências vulneráveis triadas | L7: RNF06; RNF09 | M7: Infraestrutura | N7: .venv incompleta; Python README 3.11 versus teste 3.14; quatro alertas npm | O7: =IF(AND(COUNTIF($A$5:$A$49,"A01")=1,F7>MAX(SUMIF($A$5:$A$49,"A01",$G$5:$G$49))),"OK","Rever IDs/datas") -> OK
A8: E01 | B8: N2-REQ / ajustes N1 | C8: Consolidar regras de correção e acesso | D8: Eloisa Fazzio da Silva Rocha | E8: 4 | F8: 46301 | G8: 46301 | H8: A01 | I8: P0 | J8: Planejada — validar com o grupo | K8: RF/RN rastreados; aluno sem conta; liberação do gabarito e nota máxima definidos | L8: RF29–RF40; RN01–RN05; RN14 | M8: Requisitos | N8: Não criar regras sem confrontar requisitos | O8: =IF(AND(COUNTIF($A$5:$A$49,"A01")=1,F8>MAX(SUMIF($A$5:$A$49,"A01",$G$5:$G$49))),"OK","Rever IDs/datas") -> OK
A9: L01 | B9: N2-BE-01 | C9: Unificar entrypoint, contratos e camadas da API | D9: Luan Eliseu | E9: 3 | F9: 46301 | G9: 46301 | H9: A01 | I9: P0 | J9: Planejada — validar com o grupo | K9: Contrato de sessão/erros/campos definido; controllers/services/repositories sem duplicar /api e /n1 | L9: RF01–RF48; RNF08–RNF09 | M9: Backend | N9: PR #40 como referência da auditoria local; confirmar estado antes de integrar | O9: =IF(AND(COUNTIF($A$5:$A$49,"A01")=1,F9>MAX(SUMIF($A$5:$A$49,"A01",$G$5:$G$49))),"OK","Rever IDs/datas") -> OK
A10: A05 | B10: N2-DOC-01 | C10: Consolidar arquitetura em camadas e ADRs | D10: Alyson de Lima de Oliveira | E10: 5 | F10: 46302 | G10: 46308 | H10: L01, E01 | I10: P1 | J10: Planejada — validar com o grupo | K10: ADRs justificam PostgreSQL versus MySQL, cookie, domínio único, snapshots e compensação Storage | L10: RNF08–RNF09; RN14 | M10: Documentação | N10: PR #54 como referência local; confirmar estado e decisões | O10: =IF(AND(COUNTIF($A$5:$A$49,"L01")=1,COUNTIF($A$5:$A$49,"E01")=1,F10>MAX(SUMIF($A$5:$A$49,"L01",$G$5:$G$49),SUMIF($A$5:$A$49,"E01",$G$5:$G$49))),"OK","Rever IDs/datas") -> OK
A11: D02 | B11: N2-INF-02 / N2-P1-CL | C11: Revisar classes UML e conciliar DER | D11: Diego Rafael da Silva Dornelles | E11: 4 | F11: 46302 | G11: 46302 | H11: A02, E01 | I11: P0 | J11: Planejada — validar com o grupo | K11: Multiplicidades, snapshots e modelo conceitual separados do schema; passos documentados | L11: RN14; N2 Parte 1 | M11: Modelagem | N11: Modelo N2 ainda é referência de PR; não declarar implantação | O11: =IF(AND(COUNTIF($A$5:$A$49,"A02")=1,COUNTIF($A$5:$A$49,"E01")=1,F11>MAX(SUMIF($A$5:$A$49,"A02",$G$5:$G$49),SUMIF($A$5:$A$49,"E01",$G$5:$G$49))),"OK","Rever IDs/datas") -> OK
A12: E02 | B12: N2-P1-AT | C12: Revisar atividade da correção e seu passo a passo | D12: Eloisa Fazzio da Silva Rocha | E12: 4 | F12: 46302 | G12: 46302 | H12: A02, E01 | I12: P0 | J12: Planejada — validar com o grupo | K12: Fluxo normal, decisões, rejeições e falha de persistência conferidos | L12: RF31–RF40 | M12: Modelagem | N12: Rascunho fornecido; grupo valida regras de leitura | O12: =IF(AND(COUNTIF($A$5:$A$49,"A02")=1,COUNTIF($A$5:$A$49,"E01")=1,F12>MAX(SUMIF($A$5:$A$49,"A02",$G$5:$G$49),SUMIF($A$5:$A$49,"E01",$G$5:$G$49))),"OK","Rever IDs/datas") -> OK
A13: G06 | B13: N1-FE-06 / N2-BE-05 | C13: Ajustar folha impressa ao layout OMR | D13: Gabriel Koehler da Silva | E13: 4 | F13: 46302 | G13: 46302 | H13: E01 | I13: P0 | J13: Planejada — validar com o grupo | K13: A4 com QR, marcadores e grade fixa; layout acordado com Luan; impressão verificada | L13: RF26–RF28; RF31–RF37 | M13: Frontend | N13: Conferência completa de Figma e impressão ainda pendentes | O13: =IF(AND(COUNTIF($A$5:$A$49,"E01")=1,F13>MAX(SUMIF($A$5:$A$49,"E01",$G$5:$G$49))),"OK","Rever IDs/datas") -> OK
A14: A03 | B14: N2-P1-SQ | C14: Revisar sequência da correção e seu passo a passo | D14: Alyson de Lima de Oliveira | E14: 4 | F14: 46303 | G14: 46303 | H14: E02, D02, L01 | I14: P0 | J14: Planejada — validar com o grupo | K14: Lifelines, ordem das mensagens e alternativas compatíveis com atividade e classes | L14: RF31–RF40 | M14: Modelagem | N14: Sequência representa arquitetura proposta, não código homologado | O14: =IF(AND(COUNTIF($A$5:$A$49,"E02")=1,COUNTIF($A$5:$A$49,"D02")=1,COUNTIF($A$5:$A$49,"L01")=1,F14>MAX(SUMIF($A$5:$A$49,"E02",$G$5:$G$49),SUMIF($A$5:$A$49,"D02",$G$5:$G$49),SUMIF($A$5:$A$49,"L01",$G$5:$G$49))),"OK","Rever IDs/datas") -> OK
A15: D03 | B15: N2-INF-01 | C15: Validar schema, seed e migração em PostgreSQL | D15: Diego Rafael da Silva Dornelles | E15: 5 | F15: 46303 | G15: 46304 | H15: D01, L01 | I15: P0 | J15: Planejada — validar com o grupo | K15: DDL/seed executam em banco vazio e repetição não duplica dados; caminho SQL oficial definido | L15: RNF08; RN14 | M15: Banco / Infraestrutura | N15: Scripts locais preparados, execução SQL pendente | O15: =IF(AND(COUNTIF($A$5:$A$49,"D01")=1,COUNTIF($A$5:$A$49,"L01")=1,F15>MAX(SUMIF($A$5:$A$49,"D01",$G$5:$G$49),SUMIF($A$5:$A$49,"L01",$G$5:$G$49))),"OK","Rever IDs/datas") -> OK
A16: E03 | B16: N2-MER-01 | C16: Consolidar MER e cardinalidades da N2 | D16: Eloisa Fazzio da Silva Rocha | E16: 4 | F16: 46303 | G16: 46303 | H16: E01 | I16: P0 | J16: Planejada — validar com o grupo | K16: MER inclui versão, código único, snapshots e liberação do gabarito; alinhado ao DER | L16: RF14–RF30; RN14 | M16: Modelagem | N16: PR #48 como referência local; estado remoto a confirmar | O16: =IF(AND(COUNTIF($A$5:$A$49,"E01")=1,F16>MAX(SUMIF($A$5:$A$49,"E01",$G$5:$G$49))),"OK","Rever IDs/datas") -> OK
A17: A04 | B17: N2-P1 / rastreabilidade | C17: Conferir os quatro diagramas e rastrear requisitos | D17: Alyson de Lima de Oliveira | E17: 4 | F17: 46304 | G17: 46304 | H17: A02, A03, E02, D02 | I17: P0 | J17: Planejada — validar com o grupo | K17: Cada fluxo e mensagem correspondem ao mesmo cenário; índices e passos completos | L17: N2 Parte 1; RF01–RF48 | M17: Documentação | N17: Exemplo da aula ainda precisa ser disponibilizado | O17: =IF(AND(COUNTIF($A$5:$A$49,"A02")=1,COUNTIF($A$5:$A$49,"A03")=1,COUNTIF($A$5:$A$49,"E02")=1,COUNTIF($A$5:$A$49,"D02")=1,F17>MAX(SUMIF($A$5:$A$49,"A02",$G$5:$G$49),SUMIF($A$5:$A$49,"A03",$G$5:$G$49),SUMIF($A$5:$A$49,"E02",$G$5:$G$49),SUMIF($A$5:$A$49,"D02",$G$5:$G$49))),"OK","Rever IDs/datas") -> OK
A18: A09 | B18: N2-PLAN / Excel | C18: Revisar backlog, esforço e datas com o grupo | D18: Alyson de Lima de Oliveira | E18: 4 | F18: 46308 | G18: 46310 | H18: A04 | I18: P0 | J18: Planejada — validar com o grupo | K18: Cinco integrantes participam; estimativas/dependências validadas; data acadêmica confirmada | L18: Planejamento N2 | M18: Planejamento | N18: Planilha atual usa prazo provisório 13/11/2026 | O18: =IF(AND(COUNTIF($A$5:$A$49,"A04")=1,F18>MAX(SUMIF($A$5:$A$49,"A04",$G$5:$G$49))),"OK","Rever IDs/datas") -> OK
A19: E04 | B19: N2-MER-02 | C19: Completar dicionário de dados e integridade | D19: Eloisa Fazzio da Silva Rocha | E19: 4 | F19: 46308 | G19: 46308 | H19: E03, D03 | I19: P0 | J19: Planejada — validar com o grupo | K19: Colunas/tipos/FKs/constraints e campos JSON documentados com exemplos válidos | L19: RF01–RF48; RN14 | M19: Modelagem | N19: PR #49 e schema local como referências; revisar divergências | O19: =IF(AND(COUNTIF($A$5:$A$49,"E03")=1,COUNTIF($A$5:$A$49,"D03")=1,F19>MAX(SUMIF($A$5:$A$49,"E03",$G$5:$G$49),SUMIF($A$5:$A$49,"D03",$G$5:$G$49))),"OK","Rever IDs/datas") -> OK
A20: L02 | B20: N2-BE-02 | C20: Integrar conector, pool e health do banco | D20: Luan Eliseu | E20: 4 | F20: 46308 | G20: 46308 | H20: D03, L01 | I20: P0 | J20: Planejada — validar com o grupo | K20: Pool conecta, health detecta queda, migrador usa schema único e credenciais fora do Git | L20: RNF08 | M20: Backend | N20: PR #41 como referência local; integração e teste reais pendentes | O20: =IF(AND(COUNTIF($A$5:$A$49,"D03")=1,COUNTIF($A$5:$A$49,"L01")=1,F20>MAX(SUMIF($A$5:$A$49,"D03",$G$5:$G$49),SUMIF($A$5:$A$49,"L01",$G$5:$G$49))),"OK","Rever IDs/datas") -> OK
A21: A06 | B21: N2-DOC-02 / execução | C21: Atualizar guia de execução e variáveis reais | D21: Alyson de Lima de Oliveira | E21: 4 | F21: 46309 | G21: 46309 | H21: L02, D01 | I21: P1 | J21: Planejada — validar com o grupo | K21: README reproduz ambiente e entrypoint; versão Python e caminho SQL únicos; segredos exemplificados | L21: RNF09; N2 C3 | M21: Documentação | N21: Conciliar instruções atuais conflitantes Node/Python | O21: =IF(AND(COUNTIF($A$5:$A$49,"L02")=1,COUNTIF($A$5:$A$49,"D01")=1,F21>MAX(SUMIF($A$5:$A$49,"L02",$G$5:$G$49),SUMIF($A$5:$A$49,"D01",$G$5:$G$49))),"OK","Rever IDs/datas") -> OK
A22: D04 | B22: N2-INF-01 / segurança | C22: Validar RLS, acesso por professor e Storage privado | D22: Diego Rafael da Silva Dornelles | E22: 4 | F22: 46309 | G22: 46309 | H22: D03, E04 | I22: P0 | J22: Planejada — validar com o grupo | K22: Outro professor não acessa dados/imagens; chave de serviço só no backend; bucket privado validado | L22: RNF06; RF30 | M22: Infraestrutura | N22: RLS sem policies públicas local; papel de servidor ainda precisa validação | O22: =IF(AND(COUNTIF($A$5:$A$49,"D03")=1,COUNTIF($A$5:$A$49,"E04")=1,F22>MAX(SUMIF($A$5:$A$49,"D03",$G$5:$G$49),SUMIF($A$5:$A$49,"E04",$G$5:$G$49))),"OK","Rever IDs/datas") -> OK
A23: E06 | B23: N2-TEST / OMR | C23: Montar conjunto de folhas de teste OMR | D23: Eloisa Fazzio da Silva Rocha | E23: 4 | F23: 46309 | G23: 46309 | H23: G06, E04 | I23: P0 | J23: Planejada — validar com o grupo | K23: Amostras sintéticas com branco, dupla marcação, inclinação e baixa qualidade; resultados esperados | L23: RF31–RF37 | M23: Testes | N23: Sem dados pessoais reais; registrar layout e critérios de leitura | O23: =IF(AND(COUNTIF($A$5:$A$49,"G06")=1,COUNTIF($A$5:$A$49,"E04")=1,F23>MAX(SUMIF($A$5:$A$49,"G06",$G$5:$G$49),SUMIF($A$5:$A$49,"E04",$G$5:$G$49))),"OK","Rever IDs/datas") -> OK
A24: L03 | B24: N2-BE-03 / autenticação | C24: Integrar autenticação, professores e semestres reais | D24: Luan Eliseu | E24: 4 | F24: 46309 | G24: 46309 | H24: L02 | I24: P0 | J24: Planejada — validar com o grupo | K24: Login/cookie e CRUD de semestres persistem no PostgreSQL e isolam professores | L24: RF01–RF02 | M24: Backend | N24: PR #42 como referência local; não reescrever se já atendido | O24: =IF(AND(COUNTIF($A$5:$A$49,"L02")=1,F24>MAX(SUMIF($A$5:$A$49,"L02",$G$5:$G$49))),"OK","Rever IDs/datas") -> OK
A25: G01 | B25: N2-FE-01 / login | C25: Conectar login real e tratamento da sessão | D25: Gabriel Koehler da Silva | E25: 4 | F25: 46310 | G25: 46310 | H25: L03 | I25: P0 | J25: Planejada — validar com o grupo | K25: Formulário usa contrato final; 401 redireciona; Google/recuperação indicam simulação ou serviço real | L25: RF01; RNF06 | M25: Frontend | N25: PR #60 como referência local; autenticação Google não pode parecer integrada | O25: =IF(AND(COUNTIF($A$5:$A$49,"L03")=1,F25>MAX(SUMIF($A$5:$A$49,"L03",$G$5:$G$49))),"OK","Rever IDs/datas") -> OK
A26: L04 | B26: N2-BE-03 / cadastros | C26: Integrar CRUD de turmas e alunos reais | D26: Luan Eliseu | E26: 4 | F26: 46310 | G26: 46310 | H26: L03 | I26: P0 | J26: Planejada — validar com o grupo | K26: Vínculos, matrícula e validação de importação são persistentes e transacionais | L26: RF03–RF05 | M26: Backend | N26: Conferir cadastro, duplicidade e ausência de gravação parcial | O26: =IF(AND(COUNTIF($A$5:$A$49,"L03")=1,F26>MAX(SUMIF($A$5:$A$49,"L03",$G$5:$G$49))),"OK","Rever IDs/datas") -> OK
A27: D05 | B27: N2-INF-03 / hospedagem | C27: Preparar build e proxy no mesmo domínio | D27: Diego Rafael da Silva Dornelles | E27: 4 | F27: 46311 | G27: 46311 | H27: G01, A05, L02 | I27: P0 | J27: Planejada — validar com o grupo | K27: Imagem/build funciona; frontend/API com cookie no mesmo domínio; /health útil ao provedor | L27: RNF06; N2 C2 | M27: Infraestrutura | N27: Docker/Render local preparados, build e publicação pendentes | O27: =IF(AND(COUNTIF($A$5:$A$49,"G01")=1,COUNTIF($A$5:$A$49,"A05")=1,COUNTIF($A$5:$A$49,"L02")=1,F27>MAX(SUMIF($A$5:$A$49,"G01",$G$5:$G$49),SUMIF($A$5:$A$49,"A05",$G$5:$G$49),SUMIF($A$5:$A$49,"L02",$G$5:$G$49))),"OK","Rever IDs/datas") -> OK
A28: G02 | B28: N2-FE-01 / gestão | C28: Conectar semestres e turmas ao banco real | D28: Gabriel Koehler da Silva | E28: 4 | F28: 46311 | G28: 46311 | H28: L04, G01 | I28: P0 | J28: Planejada — validar com o grupo | K28: Listagem/cadastro/edição/erros funcionam com API real após reinício | L28: RF02–RF03 | M28: Frontend | N28: Preservar visual AvaliaSystem | O28: =IF(AND(COUNTIF($A$5:$A$49,"L04")=1,COUNTIF($A$5:$A$49,"G01")=1,F28>MAX(SUMIF($A$5:$A$49,"L04",$G$5:$G$49),SUMIF($A$5:$A$49,"G01",$G$5:$G$49))),"OK","Rever IDs/datas") -> OK
A29: L05 | B29: N2-BE-03 / questões | C29: Integrar CRUD e importação de questões/alternativas | D29: Luan Eliseu | E29: 4 | F29: 46311 | G29: 46311 | H29: L04 | I29: P0 | J29: Planejada — validar com o grupo | K29: Alternativas e gabarito corretos persistem; questões usadas preservam snapshots | L29: RF06–RF13; RN14 | M29: Backend | N29: Verificar limites e importação CSV/Excel conforme escopo acordado | O29: =IF(AND(COUNTIF($A$5:$A$49,"L04")=1,F29>MAX(SUMIF($A$5:$A$49,"L04",$G$5:$G$49))),"OK","Rever IDs/datas") -> OK
A30: D06 | B30: N2-INF-03 / ambiente | C30: Configurar variáveis e verificar segredos de produção | D30: Diego Rafael da Silva Dornelles | E30: 4 | F30: 46314 | G30: 46314 | H30: D05, D04 | I30: P0 | J30: Planejada — validar com o grupo | K30: Chaves no provedor, HTTPS/cookie corretos; URL e versão documentadas; segredos ausentes do ZIP | L30: RNF06; N2 C2 | M30: Infraestrutura | N30: Execução externa futura depende de autorização; agora só planejamento | O30: =IF(AND(COUNTIF($A$5:$A$49,"D05")=1,COUNTIF($A$5:$A$49,"D04")=1,F30>MAX(SUMIF($A$5:$A$49,"D05",$G$5:$G$49),SUMIF($A$5:$A$49,"D04",$G$5:$G$49))),"OK","Rever IDs/datas") -> OK
A31: G03 | B31: N2-FE / alunos | C31: Conectar alunos e importação com confirmação | D31: Gabriel Koehler da Silva | E31: 4 | F31: 46314 | G31: 46314 | H31: L04, G02 | I31: P1 | J31: Planejada — validar com o grupo | K31: Prévia mostra erros; confirmação revalida lote; zeros na matrícula preservados | L31: RF04–RF05 | M31: Frontend | N31: CSV existente; validar decisão sobre XLSX sem prometer suporte inexistente | O31: =IF(AND(COUNTIF($A$5:$A$49,"L04")=1,COUNTIF($A$5:$A$49,"G02")=1,F31>MAX(SUMIF($A$5:$A$49,"L04",$G$5:$G$49),SUMIF($A$5:$A$49,"G02",$G$5:$G$49))),"OK","Rever IDs/datas") -> OK
A32: L06 | B32: N2-BE-04 | C32: Integrar gravação atômica de avaliações e versões | D32: Luan Eliseu | E32: 6 | F32: 46314 | G32: 46315 | H32: L05 | I32: P0 | J32: Planejada — validar com o grupo | K32: Avaliação/versões/gabaritos/snapshots gravam tudo ou nada; edição posterior não altera prova | L32: RF14–RF25; RN14 | M32: Backend | N32: PR #43 como referência; testar rollback e posições embaralhadas | O32: =IF(AND(COUNTIF($A$5:$A$49,"L05")=1,F32>MAX(SUMIF($A$5:$A$49,"L05",$G$5:$G$49))),"OK","Rever IDs/datas") -> OK
A33: G04 | B33: N2-FE-02 | C33: Conectar questões, filtros e importação à API real | D33: Gabriel Koehler da Silva | E33: 5 | F33: 46315 | G33: 46316 | H33: L05, G03 | I33: P0 | J33: Planejada — validar com o grupo | K33: CRUD/importação/filtros usam dados persistidos e retornam feedback correto | L33: RF06–RF13 | M33: Frontend | N33: Remover dependência de estado mock no fluxo entregue | O33: =IF(AND(COUNTIF($A$5:$A$49,"L05")=1,COUNTIF($A$5:$A$49,"G03")=1,F33>MAX(SUMIF($A$5:$A$49,"L05",$G$5:$G$49),SUMIF($A$5:$A$49,"G03",$G$5:$G$49))),"OK","Rever IDs/datas") -> OK
A34: L07 | B34: N2-BE-05 | C34: Integrar leitura QR, alinhamento e marcações OMR | D34: Luan Eliseu | E34: 6 | F34: 46316 | G34: 46317 | H34: L06, G06, E06 | I34: P0 | J34: Planejada — validar com o grupo | K34: QR identifica versão; perspectiva alinhada; respostas/brancos/múltiplas marcações classificadas | L34: RF31–RF37; RF40 | M34: Backend | N34: PR #44 como referência; corrigir instabilidade observada no teste QR | O34: =IF(AND(COUNTIF($A$5:$A$49,"L06")=1,COUNTIF($A$5:$A$49,"G06")=1,COUNTIF($A$5:$A$49,"E06")=1,F34>MAX(SUMIF($A$5:$A$49,"L06",$G$5:$G$49),SUMIF($A$5:$A$49,"G06",$G$5:$G$49),SUMIF($A$5:$A$49,"E06",$G$5:$G$49))),"OK","Rever IDs/datas") -> OK
A35: E05 | B35: N2-TEST / integração CRUD | C35: Testar importações, persistência e isolamento | D35: Eloisa Fazzio da Silva Rocha | E35: 4 | F35: 46317 | G35: 46317 | H35: G03, G04, D04 | I35: P0 | J35: Planejada — validar com o grupo | K35: Casos positivos/negativos registrados; reinício conserva dados; dois professores isolados | L35: RF01–RF13; RNF06 | M35: Testes | N35: Testar a aplicação integrada, não só repositories isolados | O35: =IF(AND(COUNTIF($A$5:$A$49,"G03")=1,COUNTIF($A$5:$A$49,"G04")=1,COUNTIF($A$5:$A$49,"D04")=1,F35>MAX(SUMIF($A$5:$A$49,"G03",$G$5:$G$49),SUMIF($A$5:$A$49,"G04",$G$5:$G$49),SUMIF($A$5:$A$49,"D04",$G$5:$G$49))),"OK","Rever IDs/datas") -> OK
A36: G05 | B36: N2-FE-03 | C36: Conectar assistente, versões e liberação do gabarito | D36: Gabriel Koehler da Silva | E36: 5 | F36: 46317 | G36: 46318 | H36: L06, G04 | I36: P0 | J36: Planejada — validar com o grupo | K36: Quatro passos enviam contrato final; versões persistem; liberação/revogação funciona | L36: RF14–RF30 | M36: Frontend | N36: Confirmar configuração suportada e seleção por IDs | O36: =IF(AND(COUNTIF($A$5:$A$49,"L06")=1,COUNTIF($A$5:$A$49,"G04")=1,F36>MAX(SUMIF($A$5:$A$49,"L06",$G$5:$G$49),SUMIF($A$5:$A$49,"G04",$G$5:$G$49))),"OK","Rever IDs/datas") -> OK
A37: L08 | B37: N2-BE-06 / correção | C37: Integrar cálculo de nota e resultado persistente | D37: Luan Eliseu | E37: 4 | F37: 46318 | G37: 46318 | H37: L07, D04 | I37: P0 | J37: Planejada — validar com o grupo | K37: Nota usa regra acordada; branco/múltipla marcação tratados; gravação e compensação de imagem testadas | L37: RF38–RF43 | M37: Backend | N37: PR #45 como referência; não considerar Storage e SQL uma transação única | O37: =IF(AND(COUNTIF($A$5:$A$49,"L07")=1,COUNTIF($A$5:$A$49,"D04")=1,F37>MAX(SUMIF($A$5:$A$49,"L07",$G$5:$G$49),SUMIF($A$5:$A$49,"D04",$G$5:$G$49))),"OK","Rever IDs/datas") -> OK
A38: E07 | B38: N2-TEST / aluno QR | C38: Testar liberação do gabarito e estabilidade QR | D38: Eloisa Fazzio da Silva Rocha | E38: 4 | F38: 46321 | G38: 46321 | H38: G05, L06 | I38: P0 | J38: Planejada — validar com o grupo | K38: Antes da liberação bloqueia; depois mostra só alternativas; token inválido/revogado e QR variados testados | L38: RF29–RF30; RN03–RN05 | M38: Testes | N38: Falha intermitente QR registrada em VALIDACAO_LOCAL.md | O38: =IF(AND(COUNTIF($A$5:$A$49,"G05")=1,COUNTIF($A$5:$A$49,"L06")=1,F38>MAX(SUMIF($A$5:$A$49,"G05",$G$5:$G$49),SUMIF($A$5:$A$49,"L06",$G$5:$G$49))),"OK","Rever IDs/datas") -> OK
A39: G07 | B39: N2-FE-04 / correção | C39: Conectar upload e feedback da correção real | D39: Gabriel Koehler da Silva | E39: 4 | F39: 46321 | G39: 46321 | H39: G05, L08 | I39: P0 | J39: Planejada — validar com o grupo | K39: Upload multipart mostra leitura/erros/nota; nova imagem disponível quando leitura falha | L39: RF31; RF38–RF43 | M39: Frontend | N39: Estados de carregamento, falha e sucesso explícitos | O39: =IF(AND(COUNTIF($A$5:$A$49,"G05")=1,COUNTIF($A$5:$A$49,"L08")=1,F39>MAX(SUMIF($A$5:$A$49,"G05",$G$5:$G$49),SUMIF($A$5:$A$49,"L08",$G$5:$G$49))),"OK","Rever IDs/datas") -> OK
A40: L09 | B40: N2-BE-06 / Excel | C40: Implementar/verificar exportação de notas XLSX | D40: Luan Eliseu | E40: 3 | F40: 46321 | G40: 46321 | H40: L08 | I40: P1 | J40: Planejada — validar com o grupo | K40: Arquivo abre em Excel, contém turma/aluno/versão/nota e respeita autorização/filtros | L40: RF47–RF48 | M40: Backend | N40: Exportação real distinta do CSV ou botão simulado | O40: =IF(AND(COUNTIF($A$5:$A$49,"L08")=1,F40>MAX(SUMIF($A$5:$A$49,"L08",$G$5:$G$49))),"OK","Rever IDs/datas") -> OK
A41: E08 | B41: N2-TEST / correção | C41: Validar OMR, nota e falhas de persistência | D41: Eloisa Fazzio da Silva Rocha | E41: 4 | F41: 46322 | G41: 46322 | H41: G07, L08, D04 | I41: P0 | J41: Planejada — validar com o grupo | K41: Dataset passa; falha de leitura não cria resultado; SQL/Storage com erro não exibem sucesso | L41: RF31–RF43 | M41: Testes | N41: Compensação de imagem e nova correção sem duplicar resultado | O41: =IF(AND(COUNTIF($A$5:$A$49,"G07")=1,COUNTIF($A$5:$A$49,"L08")=1,COUNTIF($A$5:$A$49,"D04")=1,F41>MAX(SUMIF($A$5:$A$49,"G07",$G$5:$G$49),SUMIF($A$5:$A$49,"L08",$G$5:$G$49),SUMIF($A$5:$A$49,"D04",$G$5:$G$49))),"OK","Rever IDs/datas") -> OK
...

Sheet Distribuição
A1: Distribuição equilibrada da N2
A4: Integrante | B4: Tarefas | C4: Esforço (h) | D4: Participação | E4: Área principal
A5: Gabriel Koehler da Silva | B5: =COUNTIF('Backlog N2'!D5:D49,A5) -> 9 | C5: =SUMIF('Backlog N2'!D5:D49,A5,'Backlog N2'!E5:E49) -> 38 | D5: =C5/SUM($C$5:$C$9) -> 0.20652174 | E5: Frontend
A6: Luan Eliseu | B6: =COUNTIF('Backlog N2'!D5:D49,A6) -> 9 | C6: =SUMIF('Backlog N2'!D5:D49,A6,'Backlog N2'!E5:E49) -> 38 | D6: =C6/SUM($C$5:$C$9) -> 0.20652174 | E6: Backend
A7: Alyson de Lima de Oliveira | B7: =COUNTIF('Backlog N2'!D5:D49,A7) -> 9 | C7: =SUMIF('Backlog N2'!D5:D49,A7,'Backlog N2'!E5:E49) -> 36 | D7: =C7/SUM($C$5:$C$9) -> 0.19565217 | E7: Documentação / arquitetura
A8: Eloisa Fazzio da Silva Rocha | B8: =COUNTIF('Backlog N2'!D5:D49,A8) -> 9 | C8: =SUMIF('Backlog N2'!D5:D49,A8,'Backlog N2'!E5:E49) -> 36 | D8: =C8/SUM($C$5:$C$9) -> 0.19565217 | E8: Requisitos / testes
A9: Diego Rafael da Silva Dornelles | B9: =COUNTIF('Backlog N2'!D5:D49,A9) -> 9 | C9: =SUMIF('Backlog N2'!D5:D49,A9,'Backlog N2'!E5:E49) -> 36 | D9: =C9/SUM($C$5:$C$9) -> 0.19565217 | E9: Infraestrutura / modelagem
A11: Total | B11: =SUM(B5:B9) -> 45 | C11: =SUM(C5:C9) -> 184
A13: Cada integrante tem 9 tarefas. Esforço entre 36 e 38 horas; equilíbrio avaliado por horas e especialidade.

Sheet Cronograma
A1: Cronograma semanal — horas alocadas
B3: 46300 | C3: 46307 | D3: 46314 | E3: 46321 | F3: 46328 | G3: 46335
A4: Integrante | B4: Semana 1 | C4: Semana 2 | D4: Semana 3 | E4: Semana 4 | F4: Semana 5 | G4: Semana 6 | H4: Total
A5: Gabriel Koehler da Silva | B5: 4 | C5: 8 | D5: 14 | E5: 12 | F5: 0 | G5: 0 | H5: =SUM(B5:G5) -> 38
A6: Luan Eliseu | B6: 3 | C6: 16 | D6: 16 | E6: 3 | F6: 0 | G6: 0 | H6: =SUM(B6:G6) -> 38
A7: Alyson de Lima de Oliveira | B7: 18 | C7: 9 | D7: 0 | E7: 0 | F7: 9 | G7: 0 | H7: =SUM(B7:G7) -> 36
A8: Eloisa Fazzio da Silva Rocha | B8: 12 | C8: 8 | D8: 4 | E8: 12 | F8: 0 | G8: 0 | H8: =SUM(B8:G8) -> 36
A9: Diego Rafael da Silva Dornelles | B9: 13 | C9: 8 | D9: 4 | E9: 4 | F9: 4 | G9: 3 | H9: =SUM(B9:G9) -> 36
A12: Alocação validada: no máximo 4 h/dia por pessoa; feriados 12/10 e 02/11 excluídos. Rever esta fotografia ao editar o backlog.
A14: Marcos: diagramas revisados na primeira fase; integração antes do aceite; D09 reservado para 13/11/2026.

Sheet Rastreabilidade
A1: Diagramas e requisitos rastreados
A4: Artefato | B4: Cenário / requisitos | C4: Responsável pela revisão | D4: Tarefas relacionadas | E4: Arquivo
A5: Caso de uso | B5: UC01–UC14; RF01–RF48; aluno sem conta | C5: Alyson de Lima de Oliveira | D5: A02, A04 | E5: ../01-caso-de-uso.md
A6: Atividade | B6: UC09; RF31–RF40; erros e persistência | C6: Eloisa Fazzio da Silva Rocha | D6: E02, E08 | E6: ../02-atividade.md
A7: Classe | B7: Snapshots RN14; entidades e cardinalidades | C7: Diego Rafael da Silva Dornelles | D7: D02, D03, E03, E04 | E7: ../03-classe.md
A8: Sequência | B8: UC09; mensagens, autorização, SQL e Storage | C8: Alyson de Lima de Oliveira | D8: A03, L07, L08, E08 | E8: ../04-sequencia.md
A9: Ajustes N1 | B9: QR intermitente, ambiente, Figma, impressão, docs | C9: Gabriel Koehler da Silva | D9: D01, G06, G09, E07, A06 | E9: ../../infra/VALIDACAO_LOCAL.md
